#VRML_SIM R2022a utf8
WorldInfo {
}
Viewpoint {
  orientation 0.28716663894631345 0.6809617937976804 -0.6736663542616055 1.0986685515588246
  position -2.606511869466872 2.538879099011265 3.634435958504044
}
TexturedBackground {
}
TexturedBackgroundLight {
}
Robot {
  translation 0 0.4 0.66
  children [
    Transform {
      children [
        Shape {
          geometry Box {
            size 0.1 0.1 1.3
          }
        }
      ]
    }
    SliderJoint {
      jointParameters JointParameters {
      }
      device [
        LinearMotor {
          name "Motor_Y"
        }
        PositionSensor {
          name "Sensor_Y"
        }
      ]
      endPoint Solid {
        translation 0 -0.5 0
        children [
          SliderJoint {
            jointParameters JointParameters {
              axis 0 1 0
            }
            device [
              LinearMotor {
                name "Motor_X"
              }
              PositionSensor {
                name "Sensor_X"
              }
            ]
            endPoint Solid {
              translation -0.25 0 0
              rotation 1 0 0 0
              children [
                SliderJoint {
                  jointParameters JointParameters {
                    axis 1 0 0
                  }
                  device [
                    LinearMotor {
                      name "Motor_Z"
                      minPosition -0.35
                    }
                    PositionSensor {
                      name "Sensor_Z"
                    }
                  ]
                  endPoint Solid {
                    translation -0.05 0 0
                    children [
                      Shape {
                        appearance PBRAppearance {
                          baseColor 1 1 0
                          roughness 1
                          metalness 0
                        }
                        geometry Box {
                          size 0.4 0.05 0.05
                        }
                      }
                    ]
                    name "solid(1)"
                  }
                }
                Shape {
                  appearance PBRAppearance {
                    baseColor 0 0 1
                    roughness 1
                    metalness 0
                  }
                  geometry Box {
                    size 0.4 0.1 0.1
                  }
                }
              ]
            }
          }
          Shape {
            appearance PBRAppearance {
              baseColor 1 0 0.0156863
              roughness 1
              metalness 0
            }
            geometry Box {
              size 0.1 0.9 0.1
            }
          }
        ]
      }
    }
    Transform {
      translation 0 -1 0
      children [
        Shape {
          geometry Box {
            size 0.1 0.1 1.3
          }
        }
      ]
    }
  ]
  controller "SSP"
}
RectangleArena {
  floorSize 5 4
}
